package ejerciciosDeExcepciones;
import java.util.*;
/*
*
*
Ahora vamos a ver como podríamos lanzar nuestra excepción desde el método main.

Primeramente, con el código que mostraremos a continuación, mostraremos un mensaje
personalizado, es decir, usaremos el segundo constructor.
 *
 */
public class ClasePrincipalwithThrows2 {
/*
    public static void main(String[]args){
        // Declaro un objeto Scanner para leer los datos
        Scanner lectura= new Scanner(System.in);
        // Declaramos una variables de tipo String
        //para almacenar un número
        String num1;

        try{// Intentamos
            // Pedir el número

            System.out.println("Introduce el primer numero ");

            // Leer el número 1
            num1=lectura.nextLine();
            // Si la variable esta vacía
            if(num1.isEmpty()) {

                // Lanzamos la excepción con un mensaje personalizado
                throw new MiPropiaExcepcion("Debes introducir un número");
            }
        }
        // En caso de error mostramos ese mensaje personalizado
        catch(MiPropiaExcepcion e) {
            System.out.println(e.getMensajeError());
        }
        finally { // Finalmente, tanto si se produce error
            // como si no, cerramos el objeto lectura
            lectura.close();
        }
    }

 */
}


